<?xml version="1.0" ?>
<robot name="turtlebot3_burger_cam"
  xmlns:xacro="http://ros.org/wiki/xacro">
  
  <material name="black">
      <color rgba="0.0 0.0 0.0 1.0"/>
  </material>

  <material name="dark">
    <color rgba="0.3 0.3 0.3 1.0"/>
  </material>

  <material name="light_black">
    <color rgba="0.4 0.4 0.4 1.0"/>
  </material>

  <material name="blue">
    <color rgba="0.0 0.0 0.8 1.0"/>
  </material>

  <material name="green">
    <color rgba="0.0 0.8 0.0 1.0"/>
  </material>

  <material name="grey">
    <color rgba="0.5 0.5 0.5 1.0"/>
  </material>

  <material name="orange">
    <color rgba="1.0 0.4235 0.0392 1.0"/>
  </material>

  <material name="brown">
    <color rgba="0.8706 0.8118 0.7647 1.0"/>
  </material>

  <material name="red">
    <color rgba="0.8 0.0 0.0 1.0"/>
  </material>

  <material name="white">
    <color rgba="1.0 1.0 1.0 1.0"/>
  </material>
  
  <link name="base_footprint"/>

  <joint name="base_joint" type="fixed">
    <parent link="base_footprint"/>
    <child link="base_link"/>
    <origin xyz="0.0 0.0 0.010" rpy="0 0 0"/>
  </joint>

  <link name="base_link">
    <visual>
      <origin xyz="-0.032 0 0.0" rpy="0 0 0"/>
      <geometry>
        <mesh filename="package://leader_bot/meshes/bases/burger_base.stl" scale="0.001 0.001 0.001"/>
      </geometry>
      <material name="light_black"/>
    </visual>

    <collision>
      <origin xyz="-0.032 0 0.070" rpy="0 0 0"/>
      <geometry>
        <box size="0.140 0.140 0.143"/>
      </geometry>
    </collision>

    <inertial>
      <origin xyz="0 0 0" rpy="0 0 0"/>
      <mass value="8.2573504e-01"/>
      <inertia ixx="2.2124416e-03" ixy="-1.2294101e-05" ixz="3.4938785e-05" iyy="2.1193702e-03" iyz="-5.0120904e-06" izz="2.0064271e-03" />
    </inertial>
  </link>

   <!-- ───────────── MATERIAL DEFINITIONS ───────────── -->
  <material name="aruco_texture">
    <color rgba="1.0 1.0 1.0 1.0"/>
    <texture filename="/home/phet/formation_turtlebot/src/leader_bot/models/aruco_marker/image.png"/>
  </material>

  <!-- ───────────── ARUCO MARKER ATTACHMENT ───────────── -->
  <joint name="aruco_marker_joint" type="fixed">
    <!-- Place behind the robot (0.12 m) and 0.10 m up -->
    <origin xyz="-0.12 0 0.10" rpy="0 0 1.57"/>
    <parent link="base_link"/>
    <child link="aruco_marker_link"/>
  </joint>

  <link name="aruco_marker_link">
    <visual>
      <!-- Rotate around Y so the marker faces backward if needed -->
      <origin xyz="0 0 0" rpy="0 1.57 0"/>
      <geometry>
        <!-- A 12 cm x 12 cm marker plate, 1 mm thick -->
        <box size="0.12 0.001 0.12"/>

      </geometry>
      <material name="aruco_texture"/>
    </visual>
  </link>

  <!-- Gazebo extension for texture so it's not all white in simulation -->
  <gazebo reference="aruco_marker_link">
    <material>
      <script>
        <!-- Correct the directory for Gazebo to recognize -->
        <uri>model://aruco_marker</uri>
        <name>aruco_texture</name>
      </script>
    </material>
  </gazebo>



  <joint name="wheel_left_joint" type="continuous">
    <parent link="base_link"/>
    <child link="wheel_left_link"/>
    <origin xyz="0.0 0.08 0.023" rpy="-1.57 0 0"/>
    <axis xyz="0 0 1"/>
  </joint>

  <link name="wheel_left_link">
    <visual>
      <origin xyz="0 0 0" rpy="1.57 0 0"/>
      <geometry>
        <mesh filename="package://leader_bot/meshes/wheels/left_tire.stl" scale="0.001 0.001 0.001"/>
      </geometry>
      <material name="dark"/>
    </visual>

    <collision>
      <origin xyz="0 0 0" rpy="0 0 0"/>
      <geometry>
        <cylinder length="0.018" radius="0.033"/>
      </geometry>
    </collision>

    <inertial>
      <origin xyz="0 0 0" />
      <mass value="2.8498940e-02" />
      <inertia ixx="1.1175580e-05" ixy="-4.2369783e-11" ixz="-5.9381719e-09" iyy="1.1192413e-05" iyz="-1.4400107e-11" izz="2.0712558e-05" />
    </inertial>
  </link>

  <joint name="wheel_right_joint" type="continuous">
    <parent link="base_link"/>
    <child link="wheel_right_link"/>
    <origin xyz="0.0 -0.080 0.023" rpy="-1.57 0 0"/>
    <axis xyz="0 0 1"/>
  </joint>

  <link name="wheel_right_link">
    <visual>
      <origin xyz="0 0 0" rpy="1.57 0 0"/>
      <geometry>
        <mesh filename="package://leader_bot/meshes/wheels/right_tire.stl" scale="0.001 0.001 0.001"/>
      </geometry>
      <material name="dark"/>
    </visual>

    <collision>
      <origin xyz="0 0 0" rpy="0 0 0"/>
      <geometry>
        <cylinder length="0.018" radius="0.033"/>
      </geometry>
    </collision>

    <inertial>
      <origin xyz="0 0 0" />
      <mass value="2.8498940e-02" />
      <inertia ixx="1.1175580e-05" ixy="-4.2369783e-11" ixz="-5.9381719e-09" iyy="1.1192413e-05" iyz="-1.4400107e-11" izz="2.0712558e-05" />
    </inertial>
  </link>

  <joint name="caster_back_joint" type="fixed">
    <parent link="base_link"/>
    <child link="caster_back_link"/>
    <origin xyz="-0.081 0 -0.004" rpy="-1.57 0 0"/>
  </joint>

  <link name="caster_back_link">
    <collision>
      <origin xyz="0 0.001 0" rpy="0 0 0"/>
      <geometry>
        <box size="0.030 0.009 0.020"/>
      </geometry>
    </collision>

    <inertial>
      <origin xyz="0 0 0" />
      <mass value="0.005" />
      <inertia ixx="0.001" ixy="0.0" ixz="0.0" iyy="0.001" iyz="0.0" izz="0.001" />
    </inertial>
  </link>

  <joint name="imu_joint" type="fixed">
    <parent link="base_link"/>
    <child link="imu_link"/>
    <origin xyz="-0.032 0 0.068" rpy="0 0 0"/>
  </joint>

  <link name="imu_link"/>

  <joint name="scan_joint" type="fixed">
    <parent link="base_link"/>
    <child link="base_scan"/>
    <origin xyz="-0.032 0 0.172" rpy="0 0 0"/>
  </joint>

  <link name="base_scan">
    <visual>
      <origin xyz="0 0 0.0" rpy="0 0 0"/>
      <geometry>
        <mesh filename="package://leader_bot/meshes/sensors/lds.stl" scale="0.001 0.001 0.001"/>
      </geometry>
      <material name="dark"/>
    </visual>

    <collision>
      <origin xyz="0.015 0 -0.0065" rpy="0 0 0"/>
      <geometry>
        <cylinder length="0.0315" radius="0.055"/>
      </geometry>
    </collision>

    <inertial>
      <mass value="0.114" />
      <origin xyz="0 0 0" />
      <inertia ixx="0.001" ixy="0.0" ixz="0.0" iyy="0.001" iyz="0.0" izz="0.001" />
    </inertial>
  </link>
  
    
   
    <!-- Front Camera - Fixed Height & FOV -->
  <joint name="camera_front_joint" type="fixed">
    <origin xyz="0.025 0.000 0.10" rpy="0 0 0"/>  <!-- เปลี่ยน z เป็น 0.090 -->
    <parent link="base_link"/>
    <child link="camera_front_link"/>
  </joint>

  <link name="camera_front_link">
    <visual>
      <origin xyz="0 0 0" rpy="0 0 1.57"/>  <!-- ปรับให้ฉายภาพออกด้านหน้า -->
      <geometry>
        <box size="0.0265 0.014 0.014"/>
      </geometry>
      <material name="grey"/>
    </visual>
  </link>

  <gazebo reference="camera_front_link">
    <sensor type="camera" name="camera_front_sensor">
      <update_rate>30</update_rate>
      <always_on>true</always_on>
      <visualize>true</visualize>
      <camera>
        <horizontal_fov>1.57</horizontal_fov> <!-- ปรับ FOV ให้เท่ากับกล้องซ้ายขวา -->
        <image>
          <width>640</width>
          <height>480</height>
          <format>R8G8B8</format>
        </image>
      </camera>
      <plugin name="camera_front_plugin" filename="libgazebo_ros_camera.so">
        <frameName>camera_front_link</frameName>
      </plugin>
    </sensor>
  </gazebo>

  <!-- Back Camera - Fixed Height & FOV -->
  <joint name="camera_back_joint" type="fixed">
    <origin xyz="-0.100 0.000 0.10" rpy="0 0 3.14"/>  <!-- เปลี่ยน z เป็น 0.090 -->
    <parent link="base_link"/>
    <child link="camera_back_link"/>
  </joint>

  <link name="camera_back_link">
    <visual>
      <origin xyz="0 0 0" rpy="0 0 -1.57"/>  <!-- ปรับให้ฉายภาพออกด้านหลัง -->
      <geometry>
        <box size="0.0265 0.014 0.014"/>
      </geometry>
      <material name="grey"/>
    </visual>
  </link>

  <gazebo reference="camera_back_link">
    <sensor type="camera" name="camera_back_sensor">
      <update_rate>30</update_rate>
      <always_on>true</always_on>
      <visualize>true</visualize>
      <camera>
        <horizontal_fov>1.57</horizontal_fov>  <!-- ปรับให้เหมือนกันทุกกล้อง -->
        <image>
          <width>640</width>
          <height>480</height>
          <format>R8G8B8</format>
        </image>
      </camera>
      <plugin name="camera_back_plugin" filename="libgazebo_ros_camera.so">
        <frameName>camera_back_link</frameName>
      </plugin>
    </sensor>
  </gazebo>



    <!-- Left Camera - Positioned at the Side Center -->
  <joint name="camera_left_joint" type="fixed">
    <origin xyz="-0.03 0.050 0.10" rpy="0 0 1.57"/> 
    <parent link="base_link"/>
    <child link="camera_left_link"/>
  </joint>

  <link name="camera_left_link">
    <visual>
      <origin xyz="0 0 0" rpy="0 0 1.57"/>  <!-- ให้กล้องหันออกด้านข้าง -->
      <geometry>
        <box size="0.0265 0.014 0.014"/>
      </geometry>
      <material name="grey"/>
    </visual>
  </link>

  <!-- Right Camera - Positioned at the Side Center -->
  <joint name="camera_right_joint" type="fixed">
    <origin xyz="-0.03 -0.050 0.10" rpy="0 0 -1.57"/> 
    <parent link="base_link"/>
    <child link="camera_right_link"/>
  </joint>

  <link name="camera_right_link">
    <visual>
      <origin xyz="0 0 0" rpy="0 0 -1.57"/>  <!-- ให้กล้องหันออกด้านข้าง -->
      <geometry>
        <box size="0.0265 0.014 0.014"/>
      </geometry>
      <material name="grey"/>
    </visual>
  </link>

 

  <gazebo reference="camera_left_link">
    <sensor type="camera" name="camera_left_sensor">
      <update_rate>30</update_rate>
      <always_on>true</always_on>
      <visualize>true</visualize>
      <camera>
        <horizontal_fov>1.57</horizontal_fov>
        <image>
          <width>640</width>
          <height>480</height>
          <format>R8G8B8</format>
        </image>
      </camera>
      <plugin name="camera_left_plugin" filename="libgazebo_ros_camera.so">
        <frameName>camera_left_link</frameName>
      </plugin>
    </sensor>
  </gazebo>

  <gazebo reference="camera_right_link">
    <sensor type="camera" name="camera_right_sensor">
      <update_rate>30</update_rate>
      <always_on>true</always_on>
      <visualize>true</visualize>
      <camera>
        <horizontal_fov>1.57</horizontal_fov>
        <image>
          <width>640</width>
          <height>480</height>
          <format>R8G8B8</format>
        </image>
      </camera>
      <plugin name="camera_right_plugin" filename="libgazebo_ros_camera.so">
        <frameName>camera_right_link</frameName>
      </plugin>
    </sensor>
  </gazebo>


</robot>
